Workbook

Sheet Legend
A1: ROVA monitoring challenge workbook
A2: Plantilla para cuestionar el monitoring de ROVA (TP/FP por escenario). Cuadros de texto en español; encabezados en inglés para coincidir con los datos de origen.
A4: Cómo usarla
A5: 1 | B5: Copia las columnas A:E de tus datos (Scenarios, Time Frame, volume, Result, Orignal Hit Type) y pégalas como valores en Raw_data desde A2. Sobrescribe la fila de ejemplo (fila 2, amarilla).
A6: 2 | B6: No pegues en F:I de Raw_data: son fórmulas (Month, O/C, Scenario #, Duplicate?). Capacidad: 3.000 filas de datos y 150 escenarios únicos.
A7: 3 | B7: Revisa Parameters (celdas azules con relleno amarillo). Los umbrales de color Amber/Red son un supuesto leído del dashboard: confírmalo con los propietarios.
A8: 4 | B8: Abre Checks: todo debe decir OK antes de usar los resultados.
A9: 5 | B9: La lista de escenarios se genera sola (orden de primera aparición). Para ordenarla, copia y pega como valores en otra hoja.
A10: Hojas
A11: Summary | B11: TP y FP por escenario en 3M (Recent), Prior 3M (Older) y 6M; precisión, alertas por TP, FP ratio, cuota de FP/TP y rango por FP.
A12: Wilson | B12: Intervalos de Wilson de la precisión (3M, Prior 3M, 6M) y marcas: Low evidence, Wide interval, Colour not supported.
A13: Tests | B13: Test z de dos proporciones, test de Fisher (aprox. bilateral y unilateral), ratio de precisión Older/Recent e índice de lag. Fila TOTAL = cartera.
A14: Portfolio | B14: Precisión de cartera por índice de mes (0 a 6), con gráfico, para detectar retraso en el etiquetado (label lag).
A15: Pareto | B15: Escenarios ordenados por FP: concentración (top 5/10), cuota de TP del top 3, escenarios con cero TP y muchos FP, y columnas para registrar decisiones.
A16: Stability | B16: FP mensual por escenario (M-6 a M-1), media, desviación, CV, z del último mes, marca Spike y test retrospectivo contra el color del dashboard.
A17: Hit_type | B17: Precisión HOLD frente a STOP por escenario (6M).
A18: Heat_FP | B18: Mapa de calor del FP mensual de los 40 escenarios con más FP (orden Pareto): conteos y valor relativo a la media propia del escenario (estabilidad), con la marca Spike.
A19: Heat_FPratio | B19: FP ratio mensual como el dashboard (colores según Parameters B8 y B9) para esos 40 escenarios. Gris = menos alertas que el mínimo por mes (Parameters B17): el color no está respaldado.
A20: Heat_Scorecard | B20: Cuadro de mando de los 40 primeros: concentración (cuota de FP y TP, burden ratio), evidencia (precisión, ancho Wilson), estabilidad (lag, CV, z) y banderas, con escala de color por columna.
A21: Checks | B21: Conciliación de datos: totales, resultados distintos de TP/FP, volumen sin mes (NULL), duplicados, capacidad.
A22: Supuestos
A23: a | B23: volume = número de alertas del escenario en ese periodo (a confirmar con los propietarios: alerta = pago o caso).
A24: b | B24: 3M = meses 1 a 3 (Recent); Prior 3M = meses 4 a 6 (Older); 6M = meses 1 a 6. El mes 0 (Current, parcial) y las filas NULL quedan fuera de las ventanas.
A25: c | B25: Precisión = TP/(TP+FP). FP ratio = FP/(TP+FP) = 1 - precisión. Intervalo de Wilson al nivel de confianza de Parameters; asume alertas independientes (clientes repetidos o una red de fraude lo ensanchan).
A26: d | B26: Fisher bilateral = doble de la cola menor (aproximación conservadora). Fisher unilateral = probabilidad de ver tan pocos TP recientes o menos si no hay diferencia.
A27: e | B27: Un TP más tardío en confirmarse hace que los meses recientes parezcan peores; el índice de lag > 1 (TP concentrados en meses antiguos) apunta a ese efecto.
A28: f | B28: Con solo 6 puntos mensuales, la desviación y el z de Stability son orientativos.
A29: g | B29: Los mapas de calor cubren los 40 escenarios con más FP en 6M (orden de Pareto). Los cortes de color y el mínimo de alertas por mes son supuestos de Parameters, no umbrales documentados por ROVA.
A30: Código de color
A31: Azul sobre amarillo | B31: Celdas de entrada (datos pegados, parámetros, columnas de decisión).
A32: Negro | B32: Fórmulas. No sobrescribir.
A33: Rojo claro | B33: Marca de aviso (flag) activada.

Sheet Parameters
A1: Parameters
A2: Celdas azules con relleno amarillo = entradas editables. Todos los umbrales son supuestos de trabajo: acuérdalos con los propietarios.
A3: Parameter | B3: Value | C3: Note
A4: Confidence level | B4: 0.95 | C4: Nivel de confianza de los intervalos de Wilson.
A5: z value | B5: =NORMSINV(1-(1-B4)/2) -> 1.959964 | C5: Calculado a partir del nivel de confianza (1,96 al 95%).
A6: Min alerts (6M) for evidence | B6: 100 | C6: Por debajo: marca Low evidence. Supuesto de partida.
A7: Min TP (6M) for evidence | B7: 5 | C7: Por debajo: marca Low evidence. Supuesto de partida.
A8: Amber starts at FP ratio >= | B8: 0.93 | C8: Supuesto leído del dashboard (rojo=100%, ámbar ~93-99%, verde <93%). Confirmar.
A9: Red starts at FP ratio >= | B9: 0.995 | C9: Supuesto: el 100% mostrado incluye >=99,5%. Confirmar.
A10: High-FP percentile | B10: 0.75 | C10: Percentil de FP 6M que define 'FP alto' si no hay override.
A11: High-FP threshold (from percentile) | B11: =IFERROR(PERCENTILE(Summary!$G$5:$G$154,B10),0) -> 43 | C11: Calculado.
A12: High-FP threshold (override, optional) | C12: Rellena con un número fijo para ignorar el percentil.
A13: High-FP threshold (used) | B13: =IF(B12<>"",B12,B11) -> 43 | C13: Umbral aplicado en Pareto.
A14: Spike z threshold | B14: 2 | C14: z del último mes frente a los 5 anteriores.
A15: Significance level (alpha) | B15: 0.05 | C15: Para los tests z y Fisher. Con muchos escenarios usa 0,01 o corrige por comparaciones múltiples.
A16: Min TP (6M) to read the lag index | B16: 10 | C16: Por debajo: 'Too few TP'.
A17: Min alerts per scenario-month to show a colour | B17: 30 | C17: Heat_FPratio: por debajo la celda sale en gris (evidencia insuficiente). Supuesto de partida.

Sheet Raw_data
A1: Scenarios | B1: Time Frame | C1: volume | D1: Result | E1: Orignal Hit Type | F1: Month | G1: O/C | H1: Scenario # | I1: Duplicate? | K1: A:E = pegar datos (azul). F:I = fórmulas, no tocar. Fila 2 = ejemplo, sobrescribir.
A2: RSK RED P CVOL CVAL | B2: Last Month | C2: 43 | D2: FP | E2: STOP | F2: =IF(A2="","",IF(B2="Current Month",0,IF(B2="Last Month",1,IF(ISNUMBER(VALUE(RIGHT(B2,2))),-VALUE(RIGHT(B2,2)),"")))) -> 1 | G2: =IF(F2="","",IF(F2=0,"Current",IF(F2<=3,"Recent",IF(F2<=6,"Older","Out of range")))) -> Recent | H2: =IF(A2="","",IF(COUNTIF($A$2:A2,A2)=1,MAX($H$1:H1)+1,"")) -> 1 | I2: =IF(A2="","",IF(COUNTIFS($A$2:A2,A2,$B$2:B2,B2,$D$2:D2,D2,$E$2:E2,E2)>1,"DUP",""))
F3: =IF(A3="","",IF(B3="Current Month",0,IF(B3="Last Month",1,IF(ISNUMBER(VALUE(RIGHT(B3,2))),-VALUE(RIGHT(B3,2)),"")))) | G3: =IF(F3="","",IF(F3=0,"Current",IF(F3<=3,"Recent",IF(F3<=6,"Older","Out of range")))) | H3: =IF(A3="","",IF(COUNTIF($A$2:A3,A3)=1,MAX($H$1:H2)+1,"")) | I3: =IF(A3="","",IF(COUNTIFS($A$2:A3,A3,$B$2:B3,B3,$D$2:D3,D3,$E$2:E3,E3)>1,"DUP",""))
F4: =IF(A4="","",IF(B4="Current Month",0,IF(B4="Last Month",1,IF(ISNUMBER(VALUE(RIGHT(B4,2))),-VALUE(RIGHT(B4,2)),"")))) | G4: =IF(F4="","",IF(F4=0,"Current",IF(F4<=3,"Recent",IF(F4<=6,"Older","Out of range")))) | H4: =IF(A4="","",IF(COUNTIF($A$2:A4,A4)=1,MAX($H$1:H3)+1,"")) | I4: =IF(A4="","",IF(COUNTIFS($A$2:A4,A4,$B$2:B4,B4,$D$2:D4,D4,$E$2:E4,E4)>1,"DUP",""))
F5: =IF(A5="","",IF(B5="Current Month",0,IF(B5="Last Month",1,IF(ISNUMBER(VALUE(RIGHT(B5,2))),-VALUE(RIGHT(B5,2)),"")))) | G5: =IF(F5="","",IF(F5=0,"Current",IF(F5<=3,"Recent",IF(F5<=6,"Older","Out of range")))) | H5: =IF(A5="","",IF(COUNTIF($A$2:A5,A5)=1,MAX($H$1:H4)+1,"")) | I5: =IF(A5="","",IF(COUNTIFS($A$2:A5,A5,$B$2:B5,B5,$D$2:D5,D5,$E$2:E5,E5)>1,"DUP",""))
F6: =IF(A6="","",IF(B6="Current Month",0,IF(B6="Last Month",1,IF(ISNUMBER(VALUE(RIGHT(B6,2))),-VALUE(RIGHT(B6,2)),"")))) | G6: =IF(F6="","",IF(F6=0,"Current",IF(F6<=3,"Recent",IF(F6<=6,"Older","Out of range")))) | H6: =IF(A6="","",IF(COUNTIF($A$2:A6,A6)=1,MAX($H$1:H5)+1,"")) | I6: =IF(A6="","",IF(COUNTIFS($A$2:A6,A6,$B$2:B6,B6,$D$2:D6,D6,$E$2:E6,E6)>1,"DUP",""))
F7: =IF(A7="","",IF(B7="Current Month",0,IF(B7="Last Month",1,IF(ISNUMBER(VALUE(RIGHT(B7,2))),-VALUE(RIGHT(B7,2)),"")))) | G7: =IF(F7="","",IF(F7=0,"Current",IF(F7<=3,"Recent",IF(F7<=6,"Older","Out of range")))) | H7: =IF(A7="","",IF(COUNTIF($A$2:A7,A7)=1,MAX($H$1:H6)+1,"")) | I7: =IF(A7="","",IF(COUNTIFS($A$2:A7,A7,$B$2:B7,B7,$D$2:D7,D7,$E$2:E7,E7)>1,"DUP",""))
F8: =IF(A8="","",IF(B8="Current Month",0,IF(B8="Last Month",1,IF(ISNUMBER(VALUE(RIGHT(B8,2))),-VALUE(RIGHT(B8,2)),"")))) | G8: =IF(F8="","",IF(F8=0,"Current",IF(F8<=3,"Recent",IF(F8<=6,"Older","Out of range")))) | H8: =IF(A8="","",IF(COUNTIF($A$2:A8,A8)=1,MAX($H$1:H7)+1,"")) | I8: =IF(A8="","",IF(COUNTIFS($A$2:A8,A8,$B$2:B8,B8,$D$2:D8,D8,$E$2:E8,E8)>1,"DUP",""))
F9: =IF(A9="","",IF(B9="Current Month",0,IF(B9="Last Month",1,IF(ISNUMBER(VALUE(RIGHT(B9,2))),-VALUE(RIGHT(B9,2)),"")))) | G9: =IF(F9="","",IF(F9=0,"Current",IF(F9<=3,"Recent",IF(F9<=6,"Older","Out of range")))) | H9: =IF(A9="","",IF(COUNTIF($A$2:A9,A9)=1,MAX($H$1:H8)+1,"")) | I9: =IF(A9="","",IF(COUNTIFS($A$2:A9,A9,$B$2:B9,B9,$D$2:D9,D9,$E$2:E9,E9)>1,"DUP",""))
F10: =IF(A10="","",IF(B10="Current Month",0,IF(B10="Last Month",1,IF(ISNUMBER(VALUE(RIGHT(B10,2))),-VALUE(RIGHT(B10,2)),"")))) | G10: =IF(F10="","",IF(F10=0,"Current",IF(F10<=3,"Recent",IF(F10<=6,"Older","Out of range")))) | H10: =IF(A10="","",IF(COUNTIF($A$2:A10,A10)=1,MAX($H$1:H9)+1,"")) | I10: =IF(A10="","",IF(COUNTIFS($A$2:A10,A10,$B$2:B10,B10,$D$2:D10,D10,$E$2:E10,E10)>1,"DUP",""))
F11: =IF(A11="","",IF(B11="Current Month",0,IF(B11="Last Month",1,IF(ISNUMBER(VALUE(RIGHT(B11,2))),-VALUE(RIGHT(B11,2)),"")))) | G11: =IF(F11="","",IF(F11=0,"Current",IF(F11<=3,"Recent",IF(F11<=6,"Older","Out of range")))) | H11: =IF(A11="","",IF(COUNTIF($A$2:A11,A11)=1,MAX($H$1:H10)+1,"")) | I11: =IF(A11="","",IF(COUNTIFS($A$2:A11,A11,$B$2:B11,B11,$D$2:D11,D11,$E$2:E11,E11)>1,"DUP",""))
F12: =IF(A12="","",IF(B12="Current Month",0,IF(B12="Last Month",1,IF(ISNUMBER(VALUE(RIGHT(B12,2))),-VALUE(RIGHT(B12,2)),"")))) | G12: =IF(F12="","",IF(F12=0,"Current",IF(F12<=3,"Recent",IF(F12<=6,"Older","Out of range")))) | H12: =IF(A12="","",IF(COUNTIF($A$2:A12,A12)=1,MAX($H$1:H11)+1,"")) | I12: =IF(A12="","",IF(COUNTIFS($A$2:A12,A12,$B$2:B12,B12,$D$2:D12,D12,$E$2:E12,E12)>1,"DUP",""))
F13: =IF(A13="","",IF(B13="Current Month",0,IF(B13="Last Month",1,IF(ISNUMBER(VALUE(RIGHT(B13,2))),-VALUE(RIGHT(B13,2)),"")))) | G13: =IF(F13="","",IF(F13=0,"Current",IF(F13<=3,"Recent",IF(F13<=6,"Older","Out of range")))) | H13: =IF(A13="","",IF(COUNTIF($A$2:A13,A13)=1,MAX($H$1:H12)+1,"")) | I13: =IF(A13="","",IF(COUNTIFS($A$2:A13,A13,$B$2:B13,B13,$D$2:D13,D13,$E$2:E13,E13)>1,"DUP",""))
F14: =IF(A14="","",IF(B14="Current Month",0,IF(B14="Last Month",1,IF(ISNUMBER(VALUE(RIGHT(B14,2))),-VALUE(RIGHT(B14,2)),"")))) | G14: =IF(F14="","",IF(F14=0,"Current",IF(F14<=3,"Recent",IF(F14<=6,"Older","Out of range")))) | H14: =IF(A14="","",IF(COUNTIF($A$2:A14,A14)=1,MAX($H$1:H13)+1,"")) | I14: =IF(A14="","",IF(COUNTIFS($A$2:A14,A14,$B$2:B14,B14,$D$2:D14,D14,$E$2:E14,E14)>1,"DUP",""))
... F3001: =IF(A3001="","",IF(B3001="Current Month",0,IF(B3001="Last Month",1,IF(ISNUMBER(VALUE(RIGHT(B3001,2))),-VALUE(RIGHT(B3001,2)),"")))) | G3001: =IF(F3001="","",IF(F3001=0,"Current",IF(F3001<=3,"Recent",IF(F3001<=6,"Older","Out of range")))) | H3001: =IF(A3001="","",IF(COUNTIF($A$2:A3001,A3001)=1,MAX($H$1:H3000)+1,"")) | I3001: =IF(A3001="","",IF(COUNTIFS($A$2:A3001,A3001,$B$2:B3001,B3001,$D$2:D3001,D3001,$E$2:E3001,E3001)>1,"DUP",""))

Sheet Checks
A1: Data checks
A2: Todo debe estar en OK antes de usar los resultados.
A3: Check | B3: Value | C3: Status | D3: Note
A4: Data rows pasted (rows 2-3001) | B4: =COUNTA(Raw_data!$A$2:$A$3001) -> 1 | C4: =IF(B4>0,"OK","CHECK: no data") -> OK | D4: Se cuenta también la fila de ejemplo si no se ha sobrescrito.
A5: Rows pasted beyond row 3001 | B5: =COUNTA(Raw_data!$A$3002:$A$20000) -> 0 | C5: =IF(B5=0,"OK","CHECK: data outside range") -> OK | D5: Amplía las fórmulas de Raw_data si hay más de 3.000 filas.
A6: Total volume (all rows) | B6: =SUM(Raw_data!$C$2:$C$3001) -> 43 | C6: ="Info" -> Info | D6: Debe coincidir con la suma de tu hoja de origen.
A7: Volume labelled TP | B7: =SUMIFS(Raw_data!$C$2:$C$3001,Raw_data!$D$2:$D$3001,"TP") -> 0 | C7: ="Info" -> Info
A8: Volume labelled FP | B8: =SUMIFS(Raw_data!$C$2:$C$3001,Raw_data!$D$2:$D$3001,"FP") -> 43 | C8: ="Info" -> Info
A9: Volume with other / blank Result | B9: =B6-B7-B8 -> 0 | C9: =IF(B9=0,"OK","CHECK: Result is not only TP/FP") -> OK | D9: Busca espacios sobrantes o etiquetas distintas.
A10: Volume in month 0 (current, partial) | B10: =SUMIFS(Raw_data!$C$2:$C$3001,Raw_data!$G$2:$G$3001,"Current") -> 0 | C10: ="Info" -> Info | D10: Excluido de las ventanas 3M, Prior 3M y 6M.
A11: Volume without valid month (NULL etc.) | B11: =B6-SUMIFS(Raw_data!$C$2:$C$3001,Raw_data!$F$2:$F$3001,">=0") -> 0 | C11: =IF(B11=0,"OK","INFO: "&TEXT(B11/B6,"0.0%")&" of volume has no valid month") -> OK | D11: Reporta este volumen como incidencia de calidad de datos.
A12: Volume in months 1-6 | B12: =SUMIFS(Raw_data!$C$2:$C$3001,Raw_data!$G$2:$G$3001,"Recent")+SUMIFS(Raw_data!$C$2:$C$3001,Raw_data!$G$2:$G$3001,"Older") -> 43 | C12: ="Info" -> Info
A13: Summary alerts 6M minus months 1-6 volume | B13: =Summary!H155-B12 -> 0 | C13: =IF(B13=0,"OK","CHECK: Summary does not reconcile") -> OK | D13: Si no es 0: más de 150 escenarios o nombres con espacios distintos.
A14: Unique scenarios found | B14: =MAX(Raw_data!$H$2:$H$3001) -> 1 | C14: =IF(B14<=150,"OK","CHECK: more than 150 scenarios") -> OK | D14: Capacidad de las hojas por escenario: 150.
A15: Possible duplicate rows | B15: =COUNTIF(Raw_data!$I$2:$I$3001,"DUP") -> 0 | C15: =IF(B15=0,"OK","CHECK: see column I of Raw_data") -> OK | D15: Misma combinación escenario, periodo, resultado y tipo.

Sheet Summary
A1: Summary by scenario
A2: TP/FP por escenario en tres ventanas. Recent = meses 1-3 (3M), Older = meses 4-6 (Prior 3M), 6M = ambos. Mes 0 y NULL excluidos.
A4: Scenario | B4: TP 3M (Recent) | C4: FP 3M (Recent) | D4: TP Prior 3M (Older) | E4: FP Prior 3M (Older) | F4: TP 6M | G4: FP 6M | H4: Alerts 6M | I4: Precision 3M | J4: Precision Prior 3M | K4: Precision 6M | L4: Alerts per TP (6M) | M4: FP ratio 6M | N4: FP share (of total FP) | O4: TP share (of total TP) | P4: FP rank (1 = most FP)
A5: =IFERROR(INDEX(Raw_data!$A$2:$A$3001,MATCH(ROWS(A$5:A5),Raw_data!$H$2:$H$3001,0)),"") -> RSK RED P CVOL CVAL | B5: =IF($A5="","",SUMIFS(Raw_data!$C$2:$C$3001,Raw_data!$A$2:$A$3001,$A5,Raw_data!$D$2:$D$3001,"TP",Raw_data!$G$2:$G$3001,"Recent")) -> 0 | C5: =IF($A5="","",SUMIFS(Raw_data!$C$2:$C$3001,Raw_data!$A$2:$A$3001,$A5,Raw_data!$D$2:$D$3001,"FP",Raw_data!$G$2:$G$3001,"Recent")) -> 43 | D5: =IF($A5="","",SUMIFS(Raw_data!$C$2:$C$3001,Raw_data!$A$2:$A$3001,$A5,Raw_data!$D$2:$D$3001,"TP",Raw_data!$G$2:$G$3001,"Older")) -> 0 | E5: =IF($A5="","",SUMIFS(Raw_data!$C$2:$C$3001,Raw_data!$A$2:$A$3001,$A5,Raw_data!$D$2:$D$3001,"FP",Raw_data!$G$2:$G$3001,"Older")) -> 0 | F5: =IF($A5="","",B5+D5) -> 0 | G5: =IF($A5="","",C5+E5) -> 43 | H5: =IF($A5="","",F5+G5) -> 43 | I5: =IF($A5="","",IF(B5+C5=0,"",B5/(B5+C5))) -> 0 | J5: =IF($A5="","",IF(D5+E5=0,"",D5/(D5+E5))) | K5: =IF($A5="","",IF(H5=0,"",F5/H5)) -> 0 | L5: =IF($A5="","",IF(F5=0,"",H5/F5)) | M5: =IF($A5="","",IF(H5=0,"",G5/H5)) -> 1 | N5: =IF($A5="","",IF($G$155=0,"",G5/$G$155)) -> 1 | O5: =IF($A5="","",IF($F$155=0,"",F5/$F$155)) | P5: =IF($A5="","",RANK(G5,$G$5:$G$154)+COUNTIF($G$5:G5,G5)-1) -> 1
A6: =IFERROR(INDEX(Raw_data!$A$2:$A$3001,MATCH(ROWS(A$5:A6),Raw_data!$H$2:$H$3001,0)),"") | B6: =IF($A6="","",SUMIFS(Raw_data!$C$2:$C$3001,Raw_data!$A$2:$A$3001,$A6,Raw_data!$D$2:$D$3001,"TP",Raw_data!$G$2:$G$3001,"Recent")) | C6: =IF($A6="","",SUMIFS(Raw_data!$C$2:$C$3001,Raw_data!$A$2:$A$3001,$A6,Raw_data!$D$2:$D$3001,"FP",Raw_data!$G$2:$G$3001,"Recent")) | D6: =IF($A6="","",SUMIFS(Raw_data!$C$2:$C$3001,Raw_data!$A$2:$A$3001,$A6,Raw_data!$D$2:$D$3001,"TP",Raw_data!$G$2:$G$3001,"Older")) | E6: =IF($A6="","",SUMIFS(Raw_data!$C$2:$C$3001,Raw_data!$A$2:$A$3001,$A6,Raw_data!$D$2:$D$3001,"FP",Raw_data!$G$2:$G$3001,"Older")) | F6: =IF($A6="","",B6+D6) | G6: =IF($A6="","",C6+E6) | H6: =IF($A6="","",F6+G6) | I6: =IF($A6="","",IF(B6+C6=0,"",B6/(B6+C6))) | J6: =IF($A6="","",IF(D6+E6=0,"",D6/(D6+E6))) | K6: =IF($A6="","",IF(H6=0,"",F6/H6)) | L6: =IF($A6="","",IF(F6=0,"",H6/F6)) | M6: =IF($A6="","",IF(H6=0,"",G6/H6)) | N6: =IF($A6="","",IF($G$155=0,"",G6/$G$155)) | O6: =IF($A6="","",IF($F$155=0,"",F6/$F$155)) | P6: =IF($A6="","",RANK(G6,$G$5:$G$154)+COUNTIF($G$5:G6,G6)-1)
A7: =IFERROR(INDEX(Raw_data!$A$2:$A$3001,MATCH(ROWS(A$5:A7),Raw_data!$H$2:$H$3001,0)),"") | B7: =IF($A7="","",SUMIFS(Raw_data!$C$2:$C$3001,Raw_data!$A$2:$A$3001,$A7,Raw_data!$D$2:$D$3001,"TP",Raw_data!$G$2:$G$3001,"Recent")) | C7: =IF($A7="","",SUMIFS(Raw_data!$C$2:$C$3001,Raw_data!$A$2:$A$3001,$A7,Raw_data!$D$2:$D$3001,"FP",Raw_data!$G$2:$G$3001,"Recent")) | D7: =IF($A7="","",SUMIFS(Raw_data!$C$2:$C$3001,Raw_data!$A$2:$A$3001,$A7,Raw_data!$D$2:$D$3001,"TP",Raw_data!$G$2:$G$3001,"Older")) | E7: =IF($A7="","",SUMIFS(Raw_data!$C$2:$C$3001,Raw_data!$A$2:$A$3001,$A7,Raw_data!$D$2:$D$3001,"FP",Raw_data!$G$2:$G$3001,"Older")) | F7: =IF($A7="","",B7+D7) | G7: =IF($A7="","",C7+E7) | H7: =IF($A7="","",F7+G7) | I7: =IF($A7="","",IF(B7+C7=0,"",B7/(B7+C7))) | J7: =IF($A7="","",IF(D7+E7=0,"",D7/(D7+E7))) | K7: =IF($A7="","",IF(H7=0,"",F7/H7)) | L7: =IF($A7="","",IF(F7=0,"",H7/F7)) | M7: =IF($A7="","",IF(H7=0,"",G7/H7)) | N7: =IF($A7="","",IF($G$155=0,"",G7/$G$155)) | O7: =IF($A7="","",IF($F$155=0,"",F7/$F$155)) | P7: =IF($A7="","",RANK(G7,$G$5:$G$154)+COUNTIF($G$5:G7,G7)-1)
A8: =IFERROR(INDEX(Raw_data!$A$2:$A$3001,MATCH(ROWS(A$5:A8),Raw_data!$H$2:$H$3001,0)),"") | B8: =IF($A8="","",SUMIFS(Raw_data!$C$2:$C$3001,Raw_data!$A$2:$A$3001,$A8,Raw_data!$D$2:$D$3001,"TP",Raw_data!$G$2:$G$3001,"Recent")) | C8: =IF($A8="","",SUMIFS(Raw_data!$C$2:$C$3001,Raw_data!$A$2:$A$3001,$A8,Raw_data!$D$2:$D$3001,"FP",Raw_data!$G$2:$G$3001,"Recent")) | D8: =IF($A8="","",SUMIFS(Raw_data!$C$2:$C$3001,Raw_data!$A$2:$A$3001,$A8,Raw_data!$D$2:$D$3001,"TP",Raw_data!$G$2:$G$3001,"Older")) | E8: =IF($A8="","",SUMIFS(Raw_data!$C$2:$C$3001,Raw_data!$A$2:$A$3001,$A8,Raw_data!$D$2:$D$3001,"FP",Raw_data!$G$2:$G$3001,"Older")) | F8: =IF($A8="","",B8+D8) | G8: =IF($A8="","",C8+E8) | H8: =IF($A8="","",F8+G8) | I8: =IF($A8="","",IF(B8+C8=0,"",B8/(B8+C8))) | J8: =IF($A8="","",IF(D8+E8=0,"",D8/(D8+E8))) | K8: =IF($A8="","",IF(H8=0,"",F8/H8)) | L8: =IF($A8="","",IF(F8=0,"",H8/F8)) | M8: =IF($A8="","",IF(H8=0,"",G8/H8)) | N8: =IF($A8="","",IF($G$155=0,"",G8/$G$155)) | O8: =IF($A8="","",IF($F$155=0,"",F8/$F$155)) | P8: =IF($A8="","",RANK(G8,$G$5:$G$154)+COUNTIF($G$5:G8,G8)-1)
A9: =IFERROR(INDEX(Raw_data!$A$2:$A$3001,MATCH(ROWS(A$5:A9),Raw_data!$H$2:$H$3001,0)),"") | B9: =IF($A9="","",SUMIFS(Raw_data!$C$2:$C$3001,Raw_data!$A$2:$A$3001,$A9,Raw_data!$D$2:$D$3001,"TP",Raw_data!$G$2:$G$3001,"Recent")) | C9: =IF($A9="","",SUMIFS(Raw_data!$C$2:$C$3001,Raw_data!$A$2:$A$3001,$A9,Raw_data!$D$2:$D$3001,"FP",Raw_data!$G$2:$G$3001,"Recent")) | D9: =IF($A9="","",SUMIFS(Raw_data!$C$2:$C$3001,Raw_data!$A$2:$A$3001,$A9,Raw_data!$D$2:$D$3001,"TP",Raw_data!$G$2:$G$3001,"Older")) | E9: =IF($A9="","",SUMIFS(Raw_data!$C$2:$C$3001,Raw_data!$A$2:$A$3001,$A9,Raw_data!$D$2:$D$3001,"FP",Raw_data!$G$2:$G$3001,"Older")) | F9: =IF($A9="","",B9+D9) | G9: =IF($A9="","",C9+E9) | H9: =IF($A9="","",F9+G9) | I9: =IF($A9="","",IF(B9+C9=0,"",B9/(B9+C9))) | J9: =IF($A9="","",IF(D9+E9=0,"",D9/(D9+E9))) | K9: =IF($A9="","",IF(H9=0,"",F9/H9)) | L9: =IF($A9="","",IF(F9=0,"",H9/F9)) | M9: =IF($A9="","",IF(H9=0,"",G9/H9)) | N9: =IF($A9="","",IF($G$155=0,"",G9/$G$155)) | O9: =IF($A9="","",IF($F$155=0,"",F9/$F$155)) | P9: =IF($A9="","",RANK(G9,$G$5:$G$154)+COUNTIF($G$5:G9,G9)-1)
A10: =IFERROR(INDEX(Raw_data!$A$2:$A$3001,MATCH(ROWS(A$5:A10),Raw_data!$H$2:$H$3001,0)),"") | B10: =IF($A10="","",SUMIFS(Raw_data!$C$2:$C$3001,Raw_data!$A$2:$A$3001,$A10,Raw_data!$D$2:$D$3001,"TP",Raw_data!$G$2:$G$3001,"Recent")) | C10: =IF($A10="","",SUMIFS(Raw_data!$C$2:$C$3001,Raw_data!$A$2:$A$3001,$A10,Raw_data!$D$2:$D$3001,"FP",Raw_data!$G$2:$G$3001,"Recent")) | D10: =IF($A10="","",SUMIFS(Raw_data!$C$2:$C$3001,Raw_data!$A$2:$A$3001,$A10,Raw_data!$D$2:$D$3001,"TP",Raw_data!$G$2:$G$3001,"Older")) | E10: =IF($A10="","",SUMIFS(Raw_data!$C$2:$C$3001,Raw_data!$A$2:$A$3001,$A10,Raw_data!$D$2:$D$3001,"FP",Raw_data!$G$2:$G$3001,"Older")) | F10: =IF($A10="","",B10+D10) | G10: =IF($A10="","",C10+E10) | H10: =IF($A10="","",F10+G10) | I10: =IF($A10="","",IF(B10+C10=0,"",B10/(B10+C10))) | J10: =IF($A10="","",IF(D10+E10=0,"",D10/(D10+E10))) | K10: =IF($A10="","",IF(H10=0,"",F10/H10)) | L10: =IF($A10="","",IF(F10=0,"",H10/F10)) | M10: =IF($A10="","",IF(H10=0,"",G10/H10)) | N10: =IF($A10="","",IF($G$155=0,"",G10/$G$155)) | O10: =IF($A10="","",IF($F$155=0,"",F10/$F$155)) | P10: =IF($A10="","",RANK(G10,$G$5:$G$154)+COUNTIF($G$5:G10,G10)-1)
A11: =IFERROR(INDEX(Raw_data!$A$2:$A$3001,MATCH(ROWS(A$5:A11),Raw_data!$H$2:$H$3001,0)),"") | B11: =IF($A11="","",SUMIFS(Raw_data!$C$2:$C$3001,Raw_data!$A$2:$A$3001,$A11,Raw_data!$D$2:$D$3001,"TP",Raw_data!$G$2:$G$3001,"Recent")) | C11: =IF($A11="","",SUMIFS(Raw_data!$C$2:$C$3001,Raw_data!$A$2:$A$3001,$A11,Raw_data!$D$2:$D$3001,"FP",Raw_data!$G$2:$G$3001,"Recent")) | D11: =IF($A11="","",SUMIFS(Raw_data!$C$2:$C$3001,Raw_data!$A$2:$A$3001,$A11,Raw_data!$D$2:$D$3001,"TP",Raw_data!$G$2:$G$3001,"Older")) | E11: =IF($A11="","",SUMIFS(Raw_data!$C$2:$C$3001,Raw_data!$A$2:$A$3001,$A11,Raw_data!$D$2:$D$3001,"FP",Raw_data!$G$2:$G$3001,"Older")) | F11: =IF($A11="","",B11+D11) | G11: =IF($A11="","",C11+E11) | H11: =IF($A11="","",F11+G11) | I11: =IF($A11="","",IF(B11+C11=0,"",B11/(B11+C11))) | J11: =IF($A11="","",IF(D11+E11=0,"",D11/(D11+E11))) | K11: =IF($A11="","",IF(H11=0,"",F11/H11)) | L11: =IF($A11="","",IF(F11=0,"",H11/F11)) | M11: =IF($A11="","",IF(H11=0,"",G11/H11)) | N11: =IF($A11="","",IF($G$155=0,"",G11/$G$155)) | O11: =IF($A11="","",IF($F$155=0,"",F11/$F$155)) | P11: =IF($A11="","",RANK(G11,$G$5:$G$154)+COUNTIF($G$5:G11,G11)-1)
A12: =IFERROR(INDEX(Raw_data!$A$2:$A$3001,MATCH(ROWS(A$5:A12),Raw_data!$H$2:$H$3001,0)),"") | B12: =IF($A12="","",SUMIFS(Raw_data!$C$2:$C$3001,Raw_data!$A$2:$A$3001,$A12,Raw_data!$D$2:$D$3001,"TP",Raw_data!$G$2:$G$3001,"Recent")) | C12: =IF($A12="","",SUMIFS(Raw_data!$C$2:$C$3001,Raw_data!$A$2:$A$3001,$A12,Raw_data!$D$2:$D$3001,"FP",Raw_data!$G$2:$G$3001,"Recent")) | D12: =IF($A12="","",SUMIFS(Raw_data!$C$2:$C$3001,Raw_data!$A$2:$A$3001,$A12,Raw_data!$D$2:$D$3001,"TP",Raw_data!$G$2:$G$3001,"Older")) | E12: =IF($A12="","",SUMIFS(Raw_data!$C$2:$C$3001,Raw_data!$A$2:$A$3001,$A12,Raw_data!$D$2:$D$3001,"FP",Raw_data!$G$2:$G$3001,"Older")) | F12: =IF($A12="","",B12+D12) | G12: =IF($A12="","",C12+E12) | H12: =IF($A12="","",F12+G12) | I12: =IF($A12="","",IF(B12+C12=0,"",B12/(B12+C12))) | J12: =IF($A12="","",IF(D12+E12=0,"",D12/(D12+E12))) | K12: =IF($A12="","",IF(H12=0,"",F12/H12)) | L12: =IF($A12="","",IF(F12=0,"",H12/F12)) | M12: =IF($A12="","",IF(H12=0,"",G12/H12)) | N12: =IF($A12="","",IF($G$155=0,"",G12/$G$155)) | O12: =IF($A12="","",IF($F$155=0,"",F12/$F$155)) | P12: =IF($A12="","",RANK(G12,$G$5:$G$154)+COUNTIF($G$5:G12,G12)-1)
A13: =IFERROR(INDEX(Raw_data!$A$2:$A$3001,MATCH(ROWS(A$5:A13),Raw_data!$H$2:$H$3001,0)),"") | B13: =IF($A13="","",SUMIFS(Raw_data!$C$2:$C$3001,Raw_data!$A$2:$A$3001,$A13,Raw_data!$D$2:$D$3001,"TP",Raw_data!$G$2:$G$3001,"Recent")) | C13: =IF($A13="","",SUMIFS(Raw_data!$C$2:$C$3001,Raw_data!$A$2:$A$3001,$A13,Raw_data!$D$2:$D$3001,"FP",Raw_data!$G$2:$G$3001,"Recent")) | D13: =IF($A13="","",SUMIFS(Raw_data!$C$2:$C$3001,Raw_data!$A$2:$A$3001,$A13,Raw_data!$D$2:$D$3001,"TP",Raw_data!$G$2:$G$3001,"Older")) | E13: =IF($A13="","",SUMIFS(Raw_data!$C$2:$C$3001,Raw_data!$A$2:$A$3001,$A13,Raw_data!$D$2:$D$3001,"FP",Raw_data!$G$2:$G$3001,"Older")) | F13: =IF($A13="","",B13+D13) | G13: =IF($A13="","",C13+E13) | H13: =IF($A13="","",F13+G13) | I13: =IF($A13="","",IF(B13+C13=0,"",B13/(B13+C13))) | J13: =IF($A13="","",IF(D13+E13=0,"",D13/(D13+E13))) | K13: =IF($A13="","",IF(H13=0,"",F13/H13)) | L13: =IF($A13="","",IF(F13=0,"",H13/F13)) | M13: =IF($A13="","",IF(H13=0,"",G13/H13)) | N13: =IF($A13="","",IF($G$155=0,"",G13/$G$155)) | O13: =IF($A13="","",IF($F$155=0,"",F13/$F$155)) | P13: =IF($A13="","",RANK(G13,$G$5:$G$154)+COUNTIF($G$5:G13,G13)-1)
A14: =IFERROR(INDEX(Raw_data!$A$2:$A$3001,MATCH(ROWS(A$5:A14),Raw_data!$H$2:$H$3001,0)),"") | B14: =IF($A14="","",SUMIFS(Raw_data!$C$2:$C$3001,Raw_data!$A$2:$A$3001,$A14,Raw_data!$D$2:$D$3001,"TP",Raw_data!$G$2:$G$3001,"Recent")) | C14: =IF($A14="","",SUMIFS(Raw_data!$C$2:$C$3001,Raw_data!$A$2:$A$3001,$A14,Raw_data!$D$2:$D$3001,"FP",Raw_data!$G$2:$G$3001,"Recent")) | D14: =IF($A14="","",SUMIFS(Raw_data!$C$2:$C$3001,Raw_data!$A$2:$A$3001,$A14,Raw_data!$D$2:$D$3001,"TP",Raw_data!$G$2:$G$3001,"Older")) | E14: =IF($A14="","",SUMIFS(Raw_data!$C$2:$C$3001,Raw_data!$A$2:$A$3001,$A14,Raw_data!$D$2:$D$3001,"FP",Raw_data!$G$2:$G$3001,"Older")) | F14: =IF($A14="","",B14+D14) | G14: =IF($A14="","",C14+E14) | H14: =IF($A14="","",F14+G14) | I14: =IF($A14="","",IF(B14+C14=0,"",B14/(B14+C14))) | J14: =IF($A14="","",IF(D14+E14=0,"",D14/(D14+E14))) | K14: =IF($A14="","",IF(H14=0,"",F14/H14)) | L14: =IF($A14="","",IF(F14=0,"",H14/F14)) | M14: =IF($A14="","",IF(H14=0,"",G14/H14)) | N14: =IF($A14="","",IF($G$155=0,"",G14/$G$155)) | O14: =IF($A14="","",IF($F$155=0,"",F14/$F$155)) | P14: =IF($A14="","",RANK(G14,$G$5:$G$154)+COUNTIF($G$5:G14,G14)-1)
A15: =IFERROR(INDEX(Raw_data!$A$2:$A$3001,MATCH(ROWS(A$5:A15),Raw_data!$H$2:$H$3001,0)),"") | B15: =IF($A15="","",SUMIFS(Raw_data!$C$2:$C$3001,Raw_data!$A$2:$A$3001,$A15,Raw_data!$D$2:$D$3001,"TP",Raw_data!$G$2:$G$3001,"Recent")) | C15: =IF($A15="","",SUMIFS(Raw_data!$C$2:$C$3001,Raw_data!$A$2:$A$3001,$A15,Raw_data!$D$2:$D$3001,"FP",Raw_data!$G$2:$G$3001,"Recent")) | D15: =IF($A15="","",SUMIFS(Raw_data!$C$2:$C$3001,Raw_data!$A$2:$A$3001,$A15,Raw_data!$D$2:$D$3001,"TP",Raw_data!$G$2:$G$3001,"Older")) | E15: =IF($A15="","",SUMIFS(Raw_data!$C$2:$C$3001,Raw_data!$A$2:$A$3001,$A15,Raw_data!$D$2:$D$3001,"FP",Raw_data!$G$2:$G$3001,"Older")) | F15: =IF($A15="","",B15+D15) | G15: =IF($A15="","",C15+E15) | H15: =IF($A15="","",F15+G15) | I15: =IF($A15="","",IF(B15+C15=0,"",B15/(B15+C15))) | J15: =IF($A15="","",IF(D15+E15=0,"",D15/(D15+E15))) | K15: =IF($A15="","",IF(H15=0,"",F15/H15)) | L15: =IF($A15="","",IF(F15=0,"",H15/F15)) | M15: =IF($A15="","",IF(H15=0,"",G15/H15)) | N15: =IF($A15="","",IF($G$155=0,"",G15/$G$155)) | O15: =IF($A15="","",IF($F$155=0,"",F15/$F$155)) | P15: =IF($A15="","",RANK(G15,$G$5:$G$154)+COUNTIF($G$5:G15,G15)-1)
A16: =IFERROR(INDEX(Raw_data!$A$2:$A$3001,MATCH(ROWS(A$5:A16),Raw_data!$H$2:$H$3001,0)),"") | B16: =IF($A16="","",SUMIFS(Raw_data!$C$2:$C$3001,Raw_data!$A$2:$A$3001,$A16,Raw_data!$D$2:$D$3001,"TP",Raw_data!$G$2:$G$3001,"Recent")) | C16: =IF($A16="","",SUMIFS(Raw_data!$C$2:$C$3001,Raw_data!$A$2:$A$3001,$A16,Raw_data!$D$2:$D$3001,"FP",Raw_data!$G$2:$G$3001,"Recent")) | D16: =IF($A16="","",SUMIFS(Raw_data!$C$2:$C$3001,Raw_data!$A$2:$A$3001,$A16,Raw_data!$D$2:$D$3001,"TP",Raw_data!$G$2:$G$3001,"Older")) | E16: =IF($A16="","",SUMIFS(Raw_data!$C$2:$C$3001,Raw_data!$A$2:$A$3001,$A16,Raw_data!$D$2:$D$3001,"FP",Raw_data!$G$2:$G$3001,"Older")) | F16: =IF($A16="","",B16+D16) | G16: =IF($A16="","",C16+E16) | H16: =IF($A16="","",F16+G16) | I16: =IF($A16="","",IF(B16+C16=0,"",B16/(B16+C16))) | J16: =IF($A16="","",IF(D16+E16=0,"",D16/(D16+E16))) | K16: =IF($A16="","",IF(H16=0,"",F16/H16)) | L16: =IF($A16="","",IF(F16=0,"",H16/F16)) | M16: =IF($A16="","",IF(H16=0,"",G16/H16)) | N16: =IF($A16="","",IF($G$155=0,"",G16/$G$155)) | O16: =IF($A16="","",IF($F$155=0,"",F16/$F$155)) | P16: =IF($A16="","",RANK(G16,$G$5:$G$154)+COUNTIF($G$5:G16,G16)-1)
... A154: =IFERROR(INDEX(Raw_data!$A$2:$A$3001,MATCH(ROWS(A$5:A154),Raw_data!$H$2:$H$3001,0)),"") | B154: =IF($A154="","",SUMIFS(Raw_data!$C$2:$C$3001,Raw_data!$A$2:$A$3001,$A154,Raw_data!$D$2:$D$3001,"TP",Raw_data!$G$2:$G$3001,"Recent")) | C154: =IF($A154="","",SUMIFS(Raw_data!$C$2:$C$3001,Raw_data!$A$2:$A$3001,$A154,Raw_data!$D$2:$D$3001,"FP",Raw_data!$G$2:$G$3001,"Recent")) | D154: =IF($A154="","",SUMIFS(Raw_data!$C$2:$C$3001,Raw_data!$A$2:$A$3001,$A154,Raw_data!$D$2:$D$3001,"TP",Raw_data!$G$2:$G$3001,"Older")) | E154: =IF($A154="","",SUMIFS(Raw_data!$C$2:$C$3001,Raw_data!$A$2:$A$3001,$A154,Raw_data!$D$2:$D$3001,"FP",Raw_data!$G$2:$G$3001,"Older")) | F154: =IF($A154="","",B154+D154) | G154: =IF($A154="","",C154+E154) | H154: =IF($A154="","",F154+G154) | I154: =IF($A154="","",IF(B154+C154=0,"",B154/(B154+C154))) | J154: =IF($A154="","",IF(D154+E154=0,"",D154/(D154+E154))) | K154: =IF($A154="","",IF(H154=0,"",F154/H154)) | L154: =IF($A154="","",IF(F154=0,"",H154/F154)) | M154: =IF($A154="","",IF(H154=0,"",G154/H154)) | N154: =IF($A154="","",IF($G$155=0,"",G154/$G$155)) | O154: =IF($A154="","",IF($F$155=0,"",F154/$F$155)) | P154: =IF($A154="","",RANK(G154,$G$5:$G$154)+COUNTIF($G$5:G154,G154)-1)
A155: TOTAL | B155: =SUM(B5:B154) -> 0 | C155: =SUM(C5:C154) -> 43 | D155: =SUM(D5:D154) -> 0 | E155: =SUM(E5:E154) -> 0 | F155: =SUM(F5:F154) -> 0 | G155: =SUM(G5:G154) -> 43 | H155: =SUM(H5:H154) -> 43 | I155: =IF(B155+C155=0,"",B155/(B155+C155)) -> 0 | J155: =IF(D155+E155=0,"",D155/(D155+E155)) | K155: =IF(H155=0,"",F155/H155) -> 0 | L155: =IF(F155=0,"",H155/F155) | M155: =IF(H155=0,"",G155/H155) -> 1

Sheet Wilson
A1: Wilson intervals for precision
A2: Intervalo de Wilson de TP/(TP+FP). Banderas: Low evidence, Wide interval (ancho > precisión), Colour not supported (el intervalo del FP ratio cruza un corte de color de Parameters).
A4: Scenario | B4: n 3M | C4: Precision 3M | D4: Lower 3M | E4: Upper 3M | F4: n Prior 3M | G4: Precision Prior 3M | H4: Lower Prior 3M | I4: Upper Prior 3M | J4: n 6M | K4: Precision 6M | L4: Lower 6M | M4: Upper 6M | N4: Width 6M | O4: Alerts per TP: best case | P4: Alerts per TP: worst case | Q4: Low evidence (6M) | R4: Wide interval (6M) | S4: Colour not supported (6M) | T4: Colour not supported (3M)
A5: =IF(Summary!A5="","",Summary!A5) -> RSK RED P CVOL CVAL | B5: =IF($A5="","",Summary!B5+Summary!C5) -> 43 | C5: =IF(OR($A5="",B5=0),"",Summary!B5/B5) -> 0 | D5: =IF(OR($A5="",B5=0),"",MAX(0,(C5+Parameters!$B$5^2/(2*B5)-Parameters!$B$5*SQRT(C5*(1-C5)/B5+Parameters!$B$5^2/(4*B5^2)))/(1+Parameters!$B$5^2/B5))) -> 0 | E5: =IF(OR($A5="",B5=0),"",MIN(1,(C5+Parameters!$B$5^2/(2*B5)+Parameters!$B$5*SQRT(C5*(1-C5)/B5+Parameters!$B$5^2/(4*B5^2)))/(1+Parameters!$B$5^2/B5))) -> 0.082009803 | F5: =IF($A5="","",Summary!D5+Summary!E5) -> 0 | G5: =IF(OR($A5="",F5=0),"",Summary!D5/F5) | H5: =IF(OR($A5="",F5=0),"",MAX(0,(G5+Parameters!$B$5^2/(2*F5)-Parameters!$B$5*SQRT(G5*(1-G5)/F5+Parameters!$B$5^2/(4*F5^2)))/(1+Parameters!$B$5^2/F5))) | I5: =IF(OR($A5="",F5=0),"",MIN(1,(G5+Parameters!$B$5^2/(2*F5)+Parameters!$B$5*SQRT(G5*(1-G5)/F5+Parameters!$B$5^2/(4*F5^2)))/(1+Parameters!$B$5^2/F5))) | J5: =IF($A5="","",Summary!F5+Summary!G5) -> 43 | K5: =IF(OR($A5="",J5=0),"",Summary!F5/J5) -> 0 | L5: =IF(OR($A5="",J5=0),"",MAX(0,(K5+Parameters!$B$5^2/(2*J5)-Parameters!$B$5*SQRT(K5*(1-K5)/J5+Parameters!$B$5^2/(4*J5^2)))/(1+Parameters!$B$5^2/J5))) -> 0 | M5: =IF(OR($A5="",J5=0),"",MIN(1,(K5+Parameters!$B$5^2/(2*J5)+Parameters!$B$5*SQRT(K5*(1-K5)/J5+Parameters!$B$5^2/(4*J5^2)))/(1+Parameters!$B$5^2/J5))) -> 0.082009803 | N5: =IF(L5="","",M5-L5) -> 0.082009803 | O5: =IF(OR(M5="",M5=0),"",1/M5) -> 12.193664 | P5: =IF(OR(L5="",L5=0),"",1/L5) | Q5: =IF($A5="","",IF(OR(J5<Parameters!$B$6,Summary!F5<Parameters!$B$7),"Low evidence","")) -> Low evidence | R5: =IF(L5="","",IF((M5-L5)>K5,"Wide interval","")) -> Wide interval | S5: =IF(L5="","",IF(OR(AND(Parameters!$B$8>=1-M5,Parameters!$B$8<=1-L5),AND(Parameters!$B$9>=1-M5,Parameters!$B$9<=1-L5)),"Colour not supported","")) -> Colour not supported | T5: =IF(D5="","",IF(OR(AND(Parameters!$B$8>=1-E5,Parameters!$B$8<=1-D5),AND(Parameters!$B$9>=1-E5,Parameters!$B$9<=1-D5)),"Colour not supported","")) -> Colour not supported
A6: =IF(Summary!A6="","",Summary!A6) | B6: =IF($A6="","",Summary!B6+Summary!C6) | C6: =IF(OR($A6="",B6=0),"",Summary!B6/B6) | D6: =IF(OR($A6="",B6=0),"",MAX(0,(C6+Parameters!$B$5^2/(2*B6)-Parameters!$B$5*SQRT(C6*(1-C6)/B6+Parameters!$B$5^2/(4*B6^2)))/(1+Parameters!$B$5^2/B6))) | E6: =IF(OR($A6="",B6=0),"",MIN(1,(C6+Parameters!$B$5^2/(2*B6)+Parameters!$B$5*SQRT(C6*(1-C6)/B6+Parameters!$B$5^2/(4*B6^2)))/(1+Parameters!$B$5^2/B6))) | F6: =IF($A6="","",Summary!D6+Summary!E6) | G6: =IF(OR($A6="",F6=0),"",Summary!D6/F6) | H6: =IF(OR($A6="",F6=0),"",MAX(0,(G6+Parameters!$B$5^2/(2*F6)-Parameters!$B$5*SQRT(G6*(1-G6)/F6+Parameters!$B$5^2/(4*F6^2)))/(1+Parameters!$B$5^2/F6))) | I6: =IF(OR($A6="",F6=0),"",MIN(1,(G6+Parameters!$B$5^2/(2*F6)+Parameters!$B$5*SQRT(G6*(1-G6)/F6+Parameters!$B$5^2/(4*F6^2)))/(1+Parameters!$B$5^2/F6))) | J6: =IF($A6="","",Summary!F6+Summary!G6) | K6: =IF(OR($A6="",J6=0),"",Summary!F6/J6) | L6: =IF(OR($A6="",J6=0),"",MAX(0,(K6+Parameters!$B$5^2/(2*J6)-Parameters!$B$5*SQRT(K6*(1-K6)/J6+Parameters!$B$5^2/(4*J6^2)))/(1+Parameters!$B$5^2/J6))) | M6: =IF(OR($A6="",J6=0),"",MIN(1,(K6+Parameters!$B$5^2/(2*J6)+Parameters!$B$5*SQRT(K6*(1-K6)/J6+Parameters!$B$5^2/(4*J6^2)))/(1+Parameters!$B$5^2/J6))) | N6: =IF(L6="","",M6-L6) | O6: =IF(OR(M6="",M6=0),"",1/M6) | P6: =IF(OR(L6="",L6=0),"",1/L6) | Q6: =IF($A6="","",IF(OR(J6<Parameters!$B$6,Summary!F6<Parameters!$B$7),"Low evidence","")) | R6: =IF(L6="","",IF((M6-L6)>K6,"Wide interval","")) | S6: =IF(L6="","",IF(OR(AND(Parameters!$B$8>=1-M6,Parameters!$B$8<=1-L6),AND(Parameters!$B$9>=1-M6,Parameters!$B$9<=1-L6)),"Colour not supported","")) | T6: =IF(D6="","",IF(OR(AND(Parameters!$B$8>=1-E6,Parameters!$B$8<=1-D6),AND(Parameters!$B$9>=1-E6,Parameters!$B$9<=1-D6)),"Colour not supported",""))
A7: =IF(Summary!A7="","",Summary!A7) | B7: =IF($A7="","",Summary!B7+Summary!C7) | C7: =IF(OR($A7="",B7=0),"",Summary!B7/B7) | D7: =IF(OR($A7="",B7=0),"",MAX(0,(C7+Parameters!$B$5^2/(2*B7)-Parameters!$B$5*SQRT(C7*(1-C7)/B7+Parameters!$B$5^2/(4*B7^2)))/(1+Parameters!$B$5^2/B7))) | E7: =IF(OR($A7="",B7=0),"",MIN(1,(C7+Parameters!$B$5^2/(2*B7)+Parameters!$B$5*SQRT(C7*(1-C7)/B7+Parameters!$B$5^2/(4*B7^2)))/(1+Parameters!$B$5^2/B7))) | F7: =IF($A7="","",Summary!D7+Summary!E7) | G7: =IF(OR($A7="",F7=0),"",Summary!D7/F7) | H7: =IF(OR($A7="",F7=0),"",MAX(0,(G7+Parameters!$B$5^2/(2*F7)-Parameters!$B$5*SQRT(G7*(1-G7)/F7+Parameters!$B$5^2/(4*F7^2)))/(1+Parameters!$B$5^2/F7))) | I7: =IF(OR($A7="",F7=0),"",MIN(1,(G7+Parameters!$B$5^2/(2*F7)+Parameters!$B$5*SQRT(G7*(1-G7)/F7+Parameters!$B$5^2/(4*F7^2)))/(1+Parameters!$B$5^2/F7))) | J7: =IF($A7="","",Summary!F7+Summary!G7) | K7: =IF(OR($A7="",J7=0),"",Summary!F7/J7) | L7: =IF(OR($A7="",J7=0),"",MAX(0,(K7+Parameters!$B$5^2/(2*J7)-Parameters!$B$5*SQRT(K7*(1-K7)/J7+Parameters!$B$5^2/(4*J7^2)))/(1+Parameters!$B$5^2/J7))) | M7: =IF(OR($A7="",J7=0),"",MIN(1,(K7+Parameters!$B$5^2/(2*J7)+Parameters!$B$5*SQRT(K7*(1-K7)/J7+Parameters!$B$5^2/(4*J7^2)))/(1+Parameters!$B$5^2/J7))) | N7: =IF(L7="","",M7-L7) | O7: =IF(OR(M7="",M7=0),"",1/M7) | P7: =IF(OR(L7="",L7=0),"",1/L7) | Q7: =IF($A7="","",IF(OR(J7<Parameters!$B$6,Summary!F7<Parameters!$B$7),"Low evidence","")) | R7: =IF(L7="","",IF((M7-L7)>K7,"Wide interval","")) | S7: =IF(L7="","",IF(OR(AND(Parameters!$B$8>=1-M7,Parameters!$B$8<=1-L7),AND(Parameters!$B$9>=1-M7,Parameters!$B$9<=1-L7)),"Colour not supported","")) | T7: =IF(D7="","",IF(OR(AND(Parameters!$B$8>=1-E7,Parameters!$B$8<=1-D7),AND(Parameters!$B$9>=1-E7,Parameters!$B$9<=1-D7)),"Colour not supported",""))
A8: =IF(Summary!A8="","",Summary!A8) | B8: =IF($A8="","",Summary!B8+Summary!C8) | C8: =IF(OR($A8="",B8=0),"",Summary!B8/B8) | D8: =IF(OR($A8="",B8=0),"",MAX(0,(C8+Parameters!$B$5^2/(2*B8)-Parameters!$B$5*SQRT(C8*(1-C8)/B8+Parameters!$B$5^2/(4*B8^2)))/(1+Parameters!$B$5^2/B8))) | E8: =IF(OR($A8="",B8=0),"",MIN(1,(C8+Parameters!$B$5^2/(2*B8)+Parameters!$B$5*SQRT(C8*(1-C8)/B8+Parameters!$B$5^2/(4*B8^2)))/(1+Parameters!$B$5^2/B8))) | F8: =IF($A8="","",Summary!D8+Summary!E8) | G8: =IF(OR($A8="",F8=0),"",Summary!D8/F8) | H8: =IF(OR($A8="",F8=0),"",MAX(0,(G8+Parameters!$B$5^2/(2*F8)-Parameters!$B$5*SQRT(G8*(1-G8)/F8+Parameters!$B$5^2/(4*F8^2)))/(1+Parameters!$B$5^2/F8))) | I8: =IF(OR($A8="",F8=0),"",MIN(1,(G8+Parameters!$B$5^2/(2*F8)+Parameters!$B$5*SQRT(G8*(1-G8)/F8+Parameters!$B$5^2/(4*F8^2)))/(1+Parameters!$B$5^2/F8))) | J8: =IF($A8="","",Summary!F8+Summary!G8) | K8: =IF(OR($A8="",J8=0),"",Summary!F8/J8) | L8: =IF(OR($A8="",J8=0),"",MAX(0,(K8+Parameters!$B$5^2/(2*J8)-Parameters!$B$5*SQRT(K8*(1-K8)/J8+Parameters!$B$5^2/(4*J8^2)))/(1+Parameters!$B$5^2/J8))) | M8: =IF(OR($A8="",J8=0),"",MIN(1,(K8+Parameters!$B$5^2/(2*J8)+Parameters!$B$5*SQRT(K8*(1-K8)/J8+Parameters!$B$5^2/(4*J8^2)))/(1+Parameters!$B$5^2/J8))) | N8: =IF(L8="","",M8-L8) | O8: =IF(OR(M8="",M8=0),"",1/M8) | P8: =IF(OR(L8="",L8=0),"",1/L8) | Q8: =IF($A8="","",IF(OR(J8<Parameters!$B$6,Summary!F8<Parameters!$B$7),"Low evidence","")) | R8: =IF(L8="","",IF((M8-L8)>K8,"Wide interval","")) | S8: =IF(L8="","",IF(OR(AND(Parameters!$B$8>=1-M8,Parameters!$B$8<=1-L8),AND(Parameters!$B$9>=1-M8,Parameters!$B$9<=1-L8)),"Colour not supported","")) | T8: =IF(D8="","",IF(OR(AND(Parameters!$B$8>=1-E8,Parameters!$B$8<=1-D8),AND(Parameters!$B$9>=1-E8,Parameters!$B$9<=1-D8)),"Colour not supported",""))
A9: =IF(Summary!A9="","",Summary!A9) | B9: =IF($A9="","",Summary!B9+Summary!C9) | C9: =IF(OR($A9="",B9=0),"",Summary!B9/B9) | D9: =IF(OR($A9="",B9=0),"",MAX(0,(C9+Parameters!$B$5^2/(2*B9)-Parameters!$B$5*SQRT(C9*(1-C9)/B9+Parameters!$B$5^2/(4*B9^2)))/(1+Parameters!$B$5^2/B9))) | E9: =IF(OR($A9="",B9=0),"",MIN(1,(C9+Parameters!$B$5^2/(2*B9)+Parameters!$B$5*SQRT(C9*(1-C9)/B9+Parameters!$B$5^2/(4*B9^2)))/(1+Parameters!$B$5^2/B9))) | F9: =IF($A9="","",Summary!D9+Summary!E9) | G9: =IF(OR($A9="",F9=0),"",Summary!D9/F9) | H9: =IF(OR($A9="",F9=0),"",MAX(0,(G9+Parameters!$B$5^2/(2*F9)-Parameters!$B$5*SQRT(G9*(1-G9)/F9+Parameters!$B$5^2/(4*F9^2)))/(1+Parameters!$B$5^2/F9))) | I9: =IF(OR($A9="",F9=0),"",MIN(1,(G9+Parameters!$B$5^2/(2*F9)+Parameters!$B$5*SQRT(G9*(1-G9)/F9+Parameters!$B$5^2/(4*F9^2)))/(1+Parameters!$B$5^2/F9))) | J9: =IF($A9="","",Summary!F9+Summary!G9) | K9: =IF(OR($A9="",J9=0),"",Summary!F9/J9) | L9: =IF(OR($A9="",J9=0),"",MAX(0,(K9+Parameters!$B$5^2/(2*J9)-Parameters!$B$5*SQRT(K9*(1-K9)/J9+Parameters!$B$5^2/(4*J9^2)))/(1+Parameters!$B$5^2/J9))) | M9: =IF(OR($A9="",J9=0),"",MIN(1,(K9+Parameters!$B$5^2/(2*J9)+Parameters!$B$5*SQRT(K9*(1-K9)/J9+Parameters!$B$5^2/(4*J9^2)))/(1+Parameters!$B$5^2/J9))) | N9: =IF(L9="","",M9-L9) | O9: =IF(OR(M9="",M9=0),"",1/M9) | P9: =IF(OR(L9="",L9=0),"",1/L9) | Q9: =IF($A9="","",IF(OR(J9<Parameters!$B$6,Summary!F9<Parameters!$B$7),"Low evidence","")) | R9: =IF(L9="","",IF((M9-L9)>K9,"Wide interval","")) | S9: =IF(L9="","",IF(OR(AND(Parameters!$B$8>=1-M9,Parameters!$B$8<=1-L9),AND(Parameters!$B$9>=1-M9,Parameters!$B$9<=1-L9)),"Colour not supported","")) | T9: =IF(D9="","",IF(OR(AND(Parameters!$B$8>=1-E9,Parameters!$B$8<=1-D9),AND(Parameters!$B$9>=1-E9,Parameters!$B$9<=1-D9)),"Colour not supported",""))
A10: =IF(Summary!A10="","",Summary!A10) | B10: =IF($A10="","",Summary!B10+Summary!C10) | C10: =IF(OR($A10="",B10=0),"",Summary!B10/B10) | D10: =IF(OR($A10="",B10=0),"",MAX(0,(C10+Parameters!$B$5^2/(2*B10)-Parameters!$B$5*SQRT(C10*(1-C10)/B10+Parameters!$B$5^2/(4*B10^2)))/(1+Parameters!$B$5^2/B10))) | E10: =IF(OR($A10="",B10=0),"",MIN(1,(C10+Parameters!$B$5^2/(2*B10)+Parameters!$B$5*SQRT(C10*(1-C10)/B10+Parameters!$B$5^2/(4*B10^2)))/(1+Parameters!$B$5^2/B10))) | F10: =IF($A10="","",Summary!D10+Summary!E10) | G10: =IF(OR($A10="",F10=0),"",Summary!D10/F10) | H10: =IF(OR($A10="",F10=0),"",MAX(0,(G10+Parameters!$B$5^2/(2*F10)-Parameters!$B$5*SQRT(G10*(1-G10)/F10+Parameters!$B$5^2/(4*F10^2)))/(1+Parameters!$B$5^2/F10))) | I10: =IF(OR($A10="",F10=0),"",MIN(1,(G10+Parameters!$B$5^2/(2*F10)+Parameters!$B$5*SQRT(G10*(1-G10)/F10+Parameters!$B$5^2/(4*F10^2)))/(1+Parameters!$B$5^2/F10))) | J10: =IF($A10="","",Summary!F10+Summary!G10) | K10: =IF(OR($A10="",J10=0),"",Summary!F10/J10) | L10: =IF(OR($A10="",J10=0),"",MAX(0,(K10+Parameters!$B$5^2/(2*J10)-Parameters!$B$5*SQRT(K10*(1-K10)/J10+Parameters!$B$5^2/(4*J10^2)))/(1+Parameters!$B$5^2/J10))) | M10: =IF(OR($A10="",J10=0),"",MIN(1,(K10+Parameters!$B$5^2/(2*J10)+Parameters!$B$5*SQRT(K10*(1-K10)/J10+Parameters!$B$5^2/(4*J10^2)))/(1+Parameters!$B$5^2/J10))) | N10: =IF(L10="","",M10-L10) | O10: =IF(OR(M10="",M10=0),"",1/M10) | P10: =IF(OR(L10="",L10=0),"",1/L10) | Q10: =IF($A10="","",IF(OR(J10<Parameters!$B$6,Summary!F10<Parameters!$B$7),"Low evidence","")) | R10: =IF(L10="","",IF((M10-L10)>K10,"Wide interval","")) | S10: =IF(L10="","",IF(OR(AND(Parameters!$B$8>=1-M10,Parameters!$B$8<=1-L10),AND(Parameters!$B$9>=1-M10,Parameters!$B$9<=1-L10)),"Colour not supported","")) | T10: =IF(D10="","",IF(OR(AND(Parameters!$B$8>=1-E10,Parameters!$B$8<=1-D10),AND(Parameters!$B$9>=1-E10,Parameters!$B$9<=1-D10)),"Colour not supported",""))
A11: =IF(Summary!A11="","",Summary!A11) | B11: =IF($A11="","",Summary!B11+Summary!C11) | C11: =IF(OR($A11="",B11=0),"",Summary!B11/B11) | D11: =IF(OR($A11="",B11=0),"",MAX(0,(C11+Parameters!$B$5^2/(2*B11)-Parameters!$B$5*SQRT(C11*(1-C11)/B11+Parameters!$B$5^2/(4*B11^2)))/(1+Parameters!$B$5^2/B11))) | E11: =IF(OR($A11="",B11=0),"",MIN(1,(C11+Parameters!$B$5^2/(2*B11)+Parameters!$B$5*SQRT(C11*(1-C11)/B11+Parameters!$B$5^2/(4*B11^2)))/(1+Parameters!$B$5^2/B11))) | F11: =IF($A11="","",Summary!D11+Summary!E11) | G11: =IF(OR($A11="",F11=0),"",Summary!D11/F11) | H11: =IF(OR($A11="",F11=0),"",MAX(0,(G11+Parameters!$B$5^2/(2*F11)-Parameters!$B$5*SQRT(G11*(1-G11)/F11+Parameters!$B$5^2/(4*F11^2)))/(1+Parameters!$B$5^2/F11))) | I11: =IF(OR($A11="",F11=0),"",MIN(1,(G11+Parameters!$B$5^2/(2*F11)+Parameters!$B$5*SQRT(G11*(1-G11)/F11+Parameters!$B$5^2/(4*F11^2)))/(1+Parameters!$B$5^2/F11))) | J11: =IF($A11="","",Summary!F11+Summary!G11) | K11: =IF(OR($A11="",J11=0),"",Summary!F11/J11) | L11: =IF(OR($A11="",J11=0),"",MAX(0,(K11+Parameters!$B$5^2/(2*J11)-Parameters!$B$5*SQRT(K11*(1-K11)/J11+Parameters!$B$5^2/(4*J11^2)))/(1+Parameters!$B$5^2/J11))) | M11: =IF(OR($A11="",J11=0),"",MIN(1,(K11+Parameters!$B$5^2/(2*J11)+Parameters!$B$5*SQRT(K11*(1-K11)/J11+Parameters!$B$5^2/(4*J11^2)))/(1+Parameters!$B$5^2/J11))) | N11: =IF(L11="","",M11-L11) | O11: =IF(OR(M11="",M11=0),"",1/M11) | P11: =IF(OR(L11="",L11=0),"",1/L11) | Q11: =IF($A11="","",IF(OR(J11<Parameters!$B$6,Summary!F11<Parameters!$B$7),"Low evidence","")) | R11: =IF(L11="","",IF((M11-L11)>K11,"Wide interval","")) | S11: =IF(L11="","",IF(OR(AND(Parameters!$B$8>=1-M11,Parameters!$B$8<=1-L11),AND(Parameters!$B$9>=1-M11,Parameters!$B$9<=1-L11)),"Colour not supported","")) | T11: =IF(D11="","",IF(OR(AND(Parameters!$B$8>=1-E11,Parameters!$B$8<=1-D11),AND(Parameters!$B$9>=1-E11,Parameters!$B$9<=1-D11)),"Colour not supported",""))
A12: =IF(Summary!A12="","",Summary!A12) | B12: =IF($A12="","",Summary!B12+Summary!C12) | C12: =IF(OR($A12="",B12=0),"",Summary!B12/B12) | D12: =IF(OR($A12="",B12=0),"",MAX(0,(C12+Parameters!$B$5^2/(2*B12)-Parameters!$B$5*SQRT(C12*(1-C12)/B12+Parameters!$B$5^2/(4*B12^2)))/(1+Parameters!$B$5^2/B12))) | E12: =IF(OR($A12="",B12=0),"",MIN(1,(C12+Parameters!$B$5^2/(2*B12)+Parameters!$B$5*SQRT(C12*(1-C12)/B12+Parameters!$B$5^2/(4*B12^2)))/(1+Parameters!$B$5^2/B12))) | F12: =IF($A12="","",Summary!D12+Summary!E12) | G12: =IF(OR($A12="",F12=0),"",Summary!D12/F12) | H12: =IF(OR($A12="",F12=0),"",MAX(0,(G12+Parameters!$B$5^2/(2*F12)-Parameters!$B$5*SQRT(G12*(1-G12)/F12+Parameters!$B$5^2/(4*F12^2)))/(1+Parameters!$B$5^2/F12))) | I12: =IF(OR($A12="",F12=0),"",MIN(1,(G12+Parameters!$B$5^2/(2*F12)+Parameters!$B$5*SQRT(G12*(1-G12)/F12+Parameters!$B$5^2/(4*F12^2)))/(1+Parameters!$B$5^2/F12))) | J12: =IF($A12="","",Summary!F12+Summary!G12) | K12: =IF(OR($A12="",J12=0),"",Summary!F12/J12) | L12: =IF(OR($A12="",J12=0),"",MAX(0,(K12+Parameters!$B$5^2/(2*J12)-Parameters!$B$5*SQRT(K12*(1-K12)/J12+Parameters!$B$5^2/(4*J12^2)))/(1+Parameters!$B$5^2/J12))) | M12: =IF(OR($A12="",J12=0),"",MIN(1,(K12+Parameters!$B$5^2/(2*J12)+Parameters!$B$5*SQRT(K12*(1-K12)/J12+Parameters!$B$5^2/(4*J12^2)))/(1+Parameters!$B$5^2/J12))) | N12: =IF(L12="","",M12-L12) | O12: =IF(OR(M12="",M12=0),"",1/M12) | P12: =IF(OR(L12="",L12=0),"",1/L12) | Q12: =IF($A12="","",IF(OR(J12<Parameters!$B$6,Summary!F12<Parameters!$B$7),"Low evidence","")) | R12: =IF(L12="","",IF((M12-L12)>K12,"Wide interval","")) | S12: =IF(L12="","",IF(OR(AND(Parameters!$B$8>=1-M12,Parameters!$B$8<=1-L12),AND(Parameters!$B$9>=1-M12,Parameters!$B$9<=1-L12)),"Colour not supported","")) | T12: =IF(D12="","",IF(OR(AND(Parameters!$B$8>=1-E12,Parameters!$B$8<=1-D12),AND(Parameters!$B$9>=1-E12,Parameters!$B$9<=1-D12)),"Colour not supported",""))
A13: =IF(Summary!A13="","",Summary!A13) | B13: =IF($A13="","",Summary!B13+Summary!C13) | C13: =IF(OR($A13="",B13=0),"",Summary!B13/B13) | D13: =IF(OR($A13="",B13=0),"",MAX(0,(C13+Parameters!$B$5^2/(2*B13)-Parameters!$B$5*SQRT(C13*(1-C13)/B13+Parameters!$B$5^2/(4*B13^2)))/(1+Parameters!$B$5^2/B13))) | E13: =IF(OR($A13="",B13=0),"",MIN(1,(C13+Parameters!$B$5^2/(2*B13)+Parameters!$B$5*SQRT(C13*(1-C13)/B13+Parameters!$B$5^2/(4*B13^2)))/(1+Parameters!$B$5^2/B13))) | F13: =IF($A13="","",Summary!D13+Summary!E13) | G13: =IF(OR($A13="",F13=0),"",Summary!D13/F13) | H13: =IF(OR($A13="",F13=0),"",MAX(0,(G13+Parameters!$B$5^2/(2*F13)-Parameters!$B$5*SQRT(G13*(1-G13)/F13+Parameters!$B$5^2/(4*F13^2)))/(1+Parameters!$B$5^2/F13))) | I13: =IF(OR($A13="",F13=0),"",MIN(1,(G13+Parameters!$B$5^2/(2*F13)+Parameters!$B$5*SQRT(G13*(1-G13)/F13+Parameters!$B$5^2/(4*F13^2)))/(1+Parameters!$B$5^2/F13))) | J13: =IF($A13="","",Summary!F13+Summary!G13) | K13: =IF(OR($A13="",J13=0),"",Summary!F13/J13) | L13: =IF(OR($A13="",J13=0),"",MAX(0,(K13+Parameters!$B$5^2/(2*J13)-Parameters!$B$5*SQRT(K13*(1-K13)/J13+Parameters!$B$5^2/(4*J13^2)))/(1+Parameters!$B$5^2/J13))) | M13: =IF(OR($A13="",J13=0),"",MIN(1,(K13+Parameters!$B$5^2/(2*J13)+Parameters!$B$5*SQRT(K13*(1-K13)/J13+Parameters!$B$5^2/(4*J13^2)))/(1+Parameters!$B$5^2/J13))) | N13: =IF(L13="","",M13-L13) | O13: =IF(OR(M13="",M13=0),"",1/M13) | P13: =IF(OR(L13="",L13=0),"",1/L13) | Q13: =IF($A13="","",IF(OR(J13<Parameters!$B$6,Summary!F13<Parameters!$B$7),"Low evidence","")) | R13: =IF(L13="","",IF((M13-L13)>K13,"Wide interval","")) | S13: =IF(L13="","",IF(OR(AND(Parameters!$B$8>=1-M13,Parameters!$B$8<=1-L13),AND(Parameters!$B$9>=1-M13,Parameters!$B$9<=1-L13)),"Colour not supported","")) | T13: =IF(D13="","",IF(OR(AND(Parameters!$B$8>=1-E13,Parameters!$B$8<=1-D13),AND(Parameters!$B$9>=1-E13,Parameters!$B$9<=1-D13)),"Colour not supported",""))
A14: =IF(Summary!A14="","",Summary!A14) | B14: =IF($A14="","",Summary!B14+Summary!C14) | C14: =IF(OR($A14="",B14=0),"",Summary!B14/B14) | D14: =IF(OR($A14="",B14=0),"",MAX(0,(C14+Parameters!$B$5^2/(2*B14)-Parameters!$B$5*SQRT(C14*(1-C14)/B14+Parameters!$B$5^2/(4*B14^2)))/(1+Parameters!$B$5^2/B14))) | E14: =IF(OR($A14="",B14=0),"",MIN(1,(C14+Parameters!$B$5^2/(2*B14)+Parameters!$B$5*SQRT(C14*(1-C14)/B14+Parameters!$B$5^2/(4*B14^2)))/(1+Parameters!$B$5^2/B14))) | F14: =IF($A14="","",Summary!D14+Summary!E14) | G14: =IF(OR($A14="",F14=0),"",Summary!D14/F14) | H14: =IF(OR($A14="",F14=0),"",MAX(0,(G14+Parameters!$B$5^2/(2*F14)-Parameters!$B$5*SQRT(G14*(1-G14)/F14+Parameters!$B$5^2/(4*F14^2)))/(1+Parameters!$B$5^2/F14))) | I14: =IF(OR($A14="",F14=0),"",MIN(1,(G14+Parameters!$B$5^2/(2*F14)+Parameters!$B$5*SQRT(G14*(1-G14)/F14+Parameters!$B$5^2/(4*F14^2)))/(1+Parameters!$B$5^2/F14))) | J14: =IF($A14="","",Summary!F14+Summary!G14) | K14: =IF(OR($A14="",J14=0),"",Summary!F14/J14) | L14: =IF(OR($A14="",J14=0),"",MAX(0,(K14+Parameters!$B$5^2/(2*J14)-Parameters!$B$5*SQRT(K14*(1-K14)/J14+Parameters!$B$5^2/(4*J14^2)))/(1+Parameters!$B$5^2/J14))) | M14: =IF(OR($A14="",J14=0),"",MIN(1,(K14+Parameters!$B$5^2/(2*J14)+Parameters!$B$5*SQRT(K14*(1-K14)/J14+Parameters!$B$5^2/(4*J14^2)))/(1+Parameters!$B$5^2/J14))) | N14: =IF(L14="","",M14-L14) | O14: =IF(OR(M14="",M14=0),"",1/M14) | P14: =IF(OR(L14="",L14=0),"",1/L14) | Q14: =IF($A14="","",IF(OR(J14<Parameters!$B$6,Summary!F14<Parameters!$B$7),"Low evidence","")) | R14: =IF(L14="","",IF((M14-L14)>K14,"Wide interval","")) | S14: =IF(L14="","",IF(OR(AND(Parameters!$B$8>=1-M14,Parameters!$B$8<=1-L14),AND(Parameters!$B$9>=1-M14,Parameters!$B$9<=1-L14)),"Colour not supported","")) | T14: =IF(D14="","",IF(OR(AND(Parameters!$B$8>=1-E14,Parameters!$B$8<=1-D14),AND(Parameters!$B$9>=1-E14,Parameters!$B$9<=1-D14)),"Colour not supported",""))
A15: =IF(Summary!A15="","",Summary!A15) | B15: =IF($A15="","",Summary!B15+Summary!C15) | C15: =IF(OR($A15="",B15=0),"",Summary!B15/B15) | D15: =IF(OR($A15="",B15=0),"",MAX(0,(C15+Parameters!$B$5^2/(2*B15)-Parameters!$B$5*SQRT(C15*(1-C15)/B15+Parameters!$B$5^2/(4*B15^2)))/(1+Parameters!$B$5^2/B15))) | E15: =IF(OR($A15="",B15=0),"",MIN(1,(C15+Parameters!$B$5^2/(2*B15)+Parameters!$B$5*SQRT(C15*(1-C15)/B15+Parameters!$B$5^2/(4*B15^2)))/(1+Parameters!$B$5^2/B15))) | F15: =IF($A15="","",Summary!D15+Summary!E15) | G15: =IF(OR($A15="",F15=0),"",Summary!D15/F15) | H15: =IF(OR($A15="",F15=0),"",MAX(0,(G15+Parameters!$B$5^2/(2*F15)-Parameters!$B$5*SQRT(G15*(1-G15)/F15+Parameters!$B$5^2/(4*F15^2)))/(1+Parameters!$B$5^2/F15))) | I15: =IF(OR($A15="",F15=0),"",MIN(1,(G15+Parameters!$B$5^2/(2*F15)+Parameters!$B$5*SQRT(G15*(1-G15)/F15+Parameters!$B$5^2/(4*F15^2)))/(1+Parameters!$B$5^2/F15))) | J15: =IF($A15="","",Summary!F15+Summary!G15) | K15: =IF(OR($A15="",J15=0),"",Summary!F15/J15) | L15: =IF(OR($A15="",J15=0),"",MAX(0,(K15+Parameters!$B$5^2/(2*J15)-Parameters!$B$5*SQRT(K15*(1-K15)/J15+Parameters!$B$5^2/(4*J15^2)))/(1+Parameters!$B$5^2/J15))) | M15: =IF(OR($A15="",J15=0),"",MIN(1,(K15+Parameters!$B$5^2/(2*J15)+Parameters!$B$5*SQRT(K15*(1-K15)/J15+Parameters!$B$5^2/(4*J15^2)))/(1+Parameters!$B$5^2/J15))) | N15: =IF(L15="","",M15-L15) | O15: =IF(OR(M15="",M15=0),"",1/M15) | P15: =IF(OR(L15="",L15=0),"",1/L15) | Q15: =IF($A15="","",IF(OR(J15<Parameters!$B$6,Summary!F15<Parameters!$B$7),"Low evidence","")) | R15: =IF(L15="","",IF((M15-L15)>K15,"Wide interval","")) | S15: =IF(L15="","",IF(OR(AND(Parameters!$B$8>=1-M15,Parameters!$B$8<=1-L15),AND(Parameters!$B$9>=1-M15,Parameters!$B$9<=1-L15)),"Colour not supported","")) | T15: =IF(D15="","",IF(OR(AND(Parameters!$B$8>=1-E15,Parameters!$B$8<=1-D15),AND(Parameters!$B$9>=1-E15,Parameters!$B$9<=1-D15)),"Colour not supported",""))
A16: =IF(Summary!A16="","",Summary!A16) | B16: =IF($A16="","",Summary!B16+Summary!C16) | C16: =IF(OR($A16="",B16=0),"",Summary!B16/B16) | D16: =IF(OR($A16="",B16=0),"",MAX(0,(C16+Parameters!$B$5^2/(2*B16)-Parameters!$B$5*SQRT(C16*(1-C16)/B16+Parameters!$B$5^2/(4*B16^2)))/(1+Parameters!$B$5^2/B16))) | E16: =IF(OR($A16="",B16=0),"",MIN(1,(C16+Parameters!$B$5^2/(2*B16)+Parameters!$B$5*SQRT(C16*(1-C16)/B16+Parameters!$B$5^2/(4*B16^2)))/(1+Parameters!$B$5^2/B16))) | F16: =IF($A16="","",Summary!D16+Summary!E16) | G16: =IF(OR($A16="",F16=0),"",Summary!D16/F16) | H16: =IF(OR($A16="",F16=0),"",MAX(0,(G16+Parameters!$B$5^2/(2*F16)-Parameters!$B$5*SQRT(G16*(1-G16)/F16+Parameters!$B$5^2/(4*F16^2)))/(1+Parameters!$B$5^2/F16))) | I16: =IF(OR($A16="",F16=0),"",MIN(1,(G16+Parameters!$B$5^2/(2*F16)+Parameters!$B$5*SQRT(G16*(1-G16)/F16+Parameters!$B$5^2/(4*F16^2)))/(1+Parameters!$B$5^2/F16))) | J16: =IF($A16="","",Summary!F16+Summary!G16) | K16: =IF(OR($A16="",J16=0),"",Summary!F16/J16) | L16: =IF(OR($A16="",J16=0),"",MAX(0,(K16+Parameters!$B$5^2/(2*J16)-Parameters!$B$5*SQRT(K16*(1-K16)/J16+Parameters!$B$5^2/(4*J16^2)))/(1+Parameters!$B$5^2/J16))) | M16: =IF(OR($A16="",J16=0),"",MIN(1,(K16+Parameters!$B$5^2/(2*J16)+Parameters!$B$5*SQRT(K16*(1-K16)/J16+Parameters!$B$5^2/(4*J16^2)))/(1+Parameters!$B$5^2/J16))) | N16: =IF(L16="","",M16-L16) | O16: =IF(OR(M16="",M16=0),"",1/M16) | P16: =IF(OR(L16="",L16=0),"",1/L16) | Q16: =IF($A16="","",IF(OR(J16<Parameters!$B$6,Summary!F16<Parameters!$B$7),"Low evidence","")) | R16: =IF(L16="","",IF((M16-L16)>K16,"Wide interval","")) | S16: =IF(L16="","",IF(OR(AND(Parameters!$B$8>=1-M16,Parameters!$B$8<=1-L16),AND(Parameters!$B$9>=1-M16,Parameters!$B$9<=1-L16)),"Colour not supported","")) | T16: =IF(D16="","",IF(OR(AND(Parameters!$B$8>=1-E16,Parameters!$B$8<=1-D16),AND(Parameters!$B$9>=1-E16,Parameters!$B$9<=1-D16)),"Colour not supported",""))
... A154: =IF(Summary!A154="","",Summary!A154) | B154: =IF($A154="","",Summary!B154+Summary!C154) | C154: =IF(OR($A154="",B154=0),"",Summary!B154/B154) | D154: =IF(OR($A154="",B154=0),"",MAX(0,(C154+Parameters!$B$5^2/(2*B154)-Parameters!$B$5*SQRT(C154*(1-C154)/B154+Parameters!$B$5^2/(4*B154^2)))/(1+Parameters!$B$5^2/B154))) | E154: =IF(OR($A154="",B154=0),"",MIN(1,(C154+Parameters!$B$5^2/(2*B154)+Parameters!$B$5*SQRT(C154*(1-C154)/B154+Parameters!$B$5^2/(4*B154^2)))/(1+Parameters!$B$5^2/B154))) | F154: =IF($A154="","",Summary!D154+Summary!E154) | G154: =IF(OR($A154="",F154=0),"",Summary!D154/F154) | H154: =IF(OR($A154="",F154=0),"",MAX(0,(G154+Parameters!$B$5^2/(2*F154)-Parameters!$B$5*SQRT(G154*(1-G154)/F154+Parameters!$B$5^2/(4*F154^2)))/(1+Parameters!$B$5^2/F154))) | I154: =IF(OR($A154="",F154=0),"",MIN(1,(G154+Parameters!$B$5^2/(2*F154)+Parameters!$B$5*SQRT(G154*(1-G154)/F154+Parameters!$B$5^2/(4*F154^2)))/(1+Parameters!$B$5^2/F154))) | J154: =IF($A154="","",Summary!F154+Summary!G154) | K154: =IF(OR($A154="",J154=0),"",Summary!F154/J154) | L154: =IF(OR($A154="",J154=0),"",MAX(0,(K154+Parameters!$B$5^2/(2*J154)-Parameters!$B$5*SQRT(K154*(1-K154)/J154+Parameters!$B$5^2/(4*J154^2)))/(1+Parameters!$B$5^2/J154))) | M154: =IF(OR($A154="",J154=0),"",MIN(1,(K154+Parameters!$B$5^2/(2*J154)+Parameters!$B$5*SQRT(K154*(1-K154)/J154+Parameters!$B$5^2/(4*J154^2)))/(1+Parameters!$B$5^2/J154))) | N154: =IF(L154="","",M154-L154) | O154: =IF(OR(M154="",M154=0),"",1/M154) | P154: =IF(OR(L154="",L154=0),"",1/L154) | Q154: =IF($A154="","",IF(OR(J154<Parameters!$B$6,Summary!F154<Parameters!$B$7),"Low evidence","")) | R154: =IF(L154="","",IF((M154-L154)>K154,"Wide interval","")) | S154: =IF(L154="","",IF(OR(AND(Parameters!$B$8>=1-M154,Parameters!$B$8<=1-L154),AND(Parameters!$B$9>=1-M154,Parameters!$B$9<=1-L154)),"Colour not supported","")) | T154: =IF(D154="","",IF(OR(AND(Parameters!$B$8>=1-E154,Parameters!$B$8<=1-D154),AND(Parameters!$B$9>=1-E154,Parameters!$B$9<=1-D154)),"Colour not supported",""))

Sheet Tests
A1: 3M vs Prior 3M tests
A2: Test z de dos proporciones y Fisher (Recent frente a Older). La fila TOTAL es la cartera. Fisher cuando el test z no es válido (frecuencias esperadas < 5).
A4: Scenario | B4: TP 3M | C4: FP 3M | D4: TP Prior 3M | E4: FP Prior 3M | F4: n 3M | G4: n Prior 3M | H4: Pooled precision | I4: z (3M minus Prior 3M) | J4: p-value (z, two-sided) | K4: z-test valid? | L4: Fisher p (recent lower, one-sided) | M4: Fisher p (two-sided, approx.) | N4: Precision ratio (Prior 3M / 3M) | O4: Lag index | P4: TP enough for lag index? | Q4: Result
A5: =IF(Summary!A5="","",Summary!A5) -> RSK RED P CVOL CVAL | B5: =IF($A5="","",Summary!B5) -> 0 | C5: =IF($A5="","",Summary!C5) -> 43 | D5: =IF($A5="","",Summary!D5) -> 0 | E5: =IF($A5="","",Summary!E5) -> 0 | F5: =IF($A5="","",B5+C5) -> 43 | G5: =IF($A5="","",D5+E5) -> 0 | H5: =IF($A5="","",IF(F5+G5=0,"",(B5+D5)/(F5+G5))) -> 0 | I5: =IF(OR($A5="",F5=0,G5=0,H5="",H5=0,H5=1),"",(B5/F5-D5/G5)/SQRT(H5*(1-H5)*(1/F5+1/G5))) | J5: =IF(I5="","",2*(1-NORMSDIST(ABS(I5)))) | K5: =IF($A5="","",IF(OR(H5="",F5=0,G5=0),"",IF(MIN(F5*H5,F5*(1-H5),G5*H5,G5*(1-H5))>=5,"z-test OK","Use Fisher"))) | L5: =IF(OR($A5="",F5=0,G5=0),"",_xlfn.HYPGEOM.DIST(B5,F5,B5+D5,F5+G5,TRUE())) | M5: =IF(L5="","",MIN(1,2*MIN(L5,IF(B5=0,1,1-_xlfn.HYPGEOM.DIST(B5-1,F5,B5+D5,F5+G5,TRUE()))))) | N5: =IF(OR($A5="",F5=0,G5=0),"",IF(B5=0,"",(D5/G5)/(B5/F5))) | O5: =IF(OR($A5="",F5=0,G5=0),"",IF(B5+D5=0,"",(D5/(B5+D5))/(G5/(F5+G5)))) | P5: =IF($A5="","",IF(B5+D5>=Parameters!$B$16,"OK","Too few TP")) -> Too few TP | Q5: =IF(M5="","",IF(M5<Parameters!$B$15,IF(B5/F5<D5/G5,"Significant: recent lower","Significant: recent higher"),"Not distinguishable"))
A6: =IF(Summary!A6="","",Summary!A6) | B6: =IF($A6="","",Summary!B6) | C6: =IF($A6="","",Summary!C6) | D6: =IF($A6="","",Summary!D6) | E6: =IF($A6="","",Summary!E6) | F6: =IF($A6="","",B6+C6) | G6: =IF($A6="","",D6+E6) | H6: =IF($A6="","",IF(F6+G6=0,"",(B6+D6)/(F6+G6))) | I6: =IF(OR($A6="",F6=0,G6=0,H6="",H6=0,H6=1),"",(B6/F6-D6/G6)/SQRT(H6*(1-H6)*(1/F6+1/G6))) | J6: =IF(I6="","",2*(1-NORMSDIST(ABS(I6)))) | K6: =IF($A6="","",IF(OR(H6="",F6=0,G6=0),"",IF(MIN(F6*H6,F6*(1-H6),G6*H6,G6*(1-H6))>=5,"z-test OK","Use Fisher"))) | L6: =IF(OR($A6="",F6=0,G6=0),"",_xlfn.HYPGEOM.DIST(B6,F6,B6+D6,F6+G6,TRUE())) | M6: =IF(L6="","",MIN(1,2*MIN(L6,IF(B6=0,1,1-_xlfn.HYPGEOM.DIST(B6-1,F6,B6+D6,F6+G6,TRUE()))))) | N6: =IF(OR($A6="",F6=0,G6=0),"",IF(B6=0,"",(D6/G6)/(B6/F6))) | O6: =IF(OR($A6="",F6=0,G6=0),"",IF(B6+D6=0,"",(D6/(B6+D6))/(G6/(F6+G6)))) | P6: =IF($A6="","",IF(B6+D6>=Parameters!$B$16,"OK","Too few TP")) | Q6: =IF(M6="","",IF(M6<Parameters!$B$15,IF(B6/F6<D6/G6,"Significant: recent lower","Significant: recent higher"),"Not distinguishable"))
A7: =IF(Summary!A7="","",Summary!A7) | B7: =IF($A7="","",Summary!B7) | C7: =IF($A7="","",Summary!C7) | D7: =IF($A7="","",Summary!D7) | E7: =IF($A7="","",Summary!E7) | F7: =IF($A7="","",B7+C7) | G7: =IF($A7="","",D7+E7) | H7: =IF($A7="","",IF(F7+G7=0,"",(B7+D7)/(F7+G7))) | I7: =IF(OR($A7="",F7=0,G7=0,H7="",H7=0,H7=1),"",(B7/F7-D7/G7)/SQRT(H7*(1-H7)*(1/F7+1/G7))) | J7: =IF(I7="","",2*(1-NORMSDIST(ABS(I7)))) | K7: =IF($A7="","",IF(OR(H7="",F7=0,G7=0),"",IF(MIN(F7*H7,F7*(1-H7),G7*H7,G7*(1-H7))>=5,"z-test OK","Use Fisher"))) | L7: =IF(OR($A7="",F7=0,G7=0),"",_xlfn.HYPGEOM.DIST(B7,F7,B7+D7,F7+G7,TRUE())) | M7: =IF(L7="","",MIN(1,2*MIN(L7,IF(B7=0,1,1-_xlfn.HYPGEOM.DIST(B7-1,F7,B7+D7,F7+G7,TRUE()))))) | N7: =IF(OR($A7="",F7=0,G7=0),"",IF(B7=0,"",(D7/G7)/(B7/F7))) | O7: =IF(OR($A7="",F7=0,G7=0),"",IF(B7+D7=0,"",(D7/(B7+D7))/(G7/(F7+G7)))) | P7: =IF($A7="","",IF(B7+D7>=Parameters!$B$16,"OK","Too few TP")) | Q7: =IF(M7="","",IF(M7<Parameters!$B$15,IF(B7/F7<D7/G7,"Significant: recent lower","Significant: recent higher"),"Not distinguishable"))
A8: =IF(Summary!A8="","",Summary!A8) | B8: =IF($A8="","",Summary!B8) | C8: =IF($A8="","",Summary!C8) | D8: =IF($A8="","",Summary!D8) | E8: =IF($A8="","",Summary!E8) | F8: =IF($A8="","",B8+C8) | G8: =IF($A8="","",D8+E8) | H8: =IF($A8="","",IF(F8+G8=0,"",(B8+D8)/(F8+G8))) | I8: =IF(OR($A8="",F8=0,G8=0,H8="",H8=0,H8=1),"",(B8/F8-D8/G8)/SQRT(H8*(1-H8)*(1/F8+1/G8))) | J8: =IF(I8="","",2*(1-NORMSDIST(ABS(I8)))) | K8: =IF($A8="","",IF(OR(H8="",F8=0,G8=0),"",IF(MIN(F8*H8,F8*(1-H8),G8*H8,G8*(1-H8))>=5,"z-test OK","Use Fisher"))) | L8: =IF(OR($A8="",F8=0,G8=0),"",_xlfn.HYPGEOM.DIST(B8,F8,B8+D8,F8+G8,TRUE())) | M8: =IF(L8="","",MIN(1,2*MIN(L8,IF(B8=0,1,1-_xlfn.HYPGEOM.DIST(B8-1,F8,B8+D8,F8+G8,TRUE()))))) | N8: =IF(OR($A8="",F8=0,G8=0),"",IF(B8=0,"",(D8/G8)/(B8/F8))) | O8: =IF(OR($A8="",F8=0,G8=0),"",IF(B8+D8=0,"",(D8/(B8+D8))/(G8/(F8+G8)))) | P8: =IF($A8="","",IF(B8+D8>=Parameters!$B$16,"OK","Too few TP")) | Q8: =IF(M8="","",IF(M8<Parameters!$B$15,IF(B8/F8<D8/G8,"Significant: recent lower","Significant: recent higher"),"Not distinguishable"))
